Workbook

Sheet Dashboard
A1: FIELD TEAM RISK MATRIX - MONTHLY DASHBOARD | N1: 46145 | O1: 46152
A2: Set date range: N1 = start date, O1 = end date | Update all Data tabs and regenerate Pole Results before presenting to SOMs | Complete by working day 5 each month | N2: Start date | O2: End date
A4: RISK BAND SUMMARY
A5: Active Teams | D5: LOW Risk | H5: MEDIUM Risk | L5: HIGH Risk
A6: =COUNTA('Field Teams'!B5:B204)-COUNTIF('Field Teams'!I5:I204,"Inactive") | D6: =COUNTIF('Monthly Matrix'!AA4:AA76,"LOW") | H6: =COUNTIF('Monthly Matrix'!AA4:AA76,"MEDIUM") | L6: =COUNTIF('Monthly Matrix'!AA4:AA76,"HIGH")
A7: =IF(COUNTIF('Monthly Matrix'!AA4:AA76,"HIGH")=0,"No HIGH risk teams this month","HIGH risk teams require action - see table below")
A8: =IF(COUNTIF('Monthly Matrix'!M4:M76,"YES")=0,"No Major impact events this month","MAJOR EVENT recorded - immediate escalation required")
A9: ="Total operatives in scope: "&SUM('Field Teams'!H5:H77)&" | Amber target this month: "&SUM('Monthly Matrix'!I4:I76)&" events across all teams"
A11: TOP 10 HIGHEST RISK TEAMS
A12: Rank | B12: Team | C12: Contract | D12: SOM | E12: Score | F12: RAG | G12: Amber Count | H12: Amber Target | I12: Skillko % | J12: Quality Fails | K12: Checks Assessed | L12: Compliant Checks | M12: Plan?
A13: 1 | B13: =IFERROR(INDEX('Monthly Matrix'!$B$4:$B$76,MATCH(LARGE('Monthly Matrix'!$AB$4:$AB$76,1),'Monthly Matrix'!$AB$4:$AB$76,0)),"") | C13: =IFERROR(INDEX('Monthly Matrix'!$C$4:$C$76,MATCH(LARGE('Monthly Matrix'!$AB$4:$AB$76,1),'Monthly Matrix'!$AB$4:$AB$76,0)),"") | D13: =IFERROR(INDEX('Monthly Matrix'!$E$4:$E$76,MATCH(LARGE('Monthly Matrix'!$AB$4:$AB$76,1),'Monthly Matrix'!$AB$4:$AB$76,0)),"") | E13: =IFERROR(INDEX('Monthly Matrix'!$T$4:$T$76,MATCH(LARGE('Monthly Matrix'!$AB$4:$AB$76,1),'Monthly Matrix'!$AB$4:$AB$76,0)),"") | F13: =IFERROR(INDEX('Monthly Matrix'!$V$4:$AA$76,MATCH(LARGE('Monthly Matrix'!$AB$4:$AB$76,1),'Monthly Matrix'!$AB$4:$AB$76,0)),"") | G13: =IFERROR(INDEX('Monthly Matrix'!$J$4:$J$76,MATCH(LARGE('Monthly Matrix'!$AB$4:$AB$76,1),'Monthly Matrix'!$AB$4:$AB$76,0)),"") | H13: =IFERROR(INDEX('Monthly Matrix'!$I$4:$I$76,MATCH(LARGE('Monthly Matrix'!$AB$4:$AB$76,1),'Monthly Matrix'!$AB$4:$AB$76,0)),"") | I13: =IFERROR(INDEX('Monthly Matrix'!$N$4:$N$76,MATCH(LARGE('Monthly Matrix'!$AB$4:$AB$76,1),'Monthly Matrix'!$AB$4:$AB$76,0)),"") | J13: =IFERROR(INDEX('Monthly Matrix'!$P$4:$P$76,MATCH(LARGE('Monthly Matrix'!$AB$4:$AB$76,1),'Monthly Matrix'!$AB$4:$AB$76,0)),"") | K13: =IFERROR(INDEX('Monthly Matrix'!$AH$4:$AH$76,MATCH(LARGE('Monthly Matrix'!$AB$4:$AB$76,1),'Monthly Matrix'!$AB$4:$AB$76,0)),"") | L13: =IFERROR(INDEX('Monthly Matrix'!$AI$4:$AI$76,MATCH(LARGE('Monthly Matrix'!$AB$4:$AB$76,1),'Monthly Matrix'!$AB$4:$AB$76,0))/K13,"") | M13: =IFERROR(INDEX('Monthly Matrix'!$AF$4:$AF$76,MATCH(LARGE('Monthly Matrix'!$AB$4:$AB$76,1),'Monthly Matrix'!$AB$4:$AB$76,0)),"")
A14: 2 | B14: =IFERROR(INDEX('Monthly Matrix'!$B$4:$B$76,MATCH(LARGE('Monthly Matrix'!$AB$4:$AB$76,2),'Monthly Matrix'!$AB$4:$AB$76,0)),"") | C14: =IFERROR(INDEX('Monthly Matrix'!$C$4:$C$76,MATCH(LARGE('Monthly Matrix'!$AB$4:$AB$76,2),'Monthly Matrix'!$AB$4:$AB$76,0)),"") | D14: =IFERROR(INDEX('Monthly Matrix'!$E$4:$E$76,MATCH(LARGE('Monthly Matrix'!$AB$4:$AB$76,2),'Monthly Matrix'!$AB$4:$AB$76,0)),"") | E14: =IFERROR(INDEX('Monthly Matrix'!$T$4:$T$76,MATCH(LARGE('Monthly Matrix'!$AB$4:$AB$76,2),'Monthly Matrix'!$AB$4:$AB$76,0)),"") | F14: =IFERROR(INDEX('Monthly Matrix'!$V$4:$AA$76,MATCH(LARGE('Monthly Matrix'!$AB$4:$AB$76,2),'Monthly Matrix'!$AB$4:$AB$76,0)),"") | G14: =IFERROR(INDEX('Monthly Matrix'!$J$4:$J$76,MATCH(LARGE('Monthly Matrix'!$AB$4:$AB$76,2),'Monthly Matrix'!$AB$4:$AB$76,0)),"") | H14: =IFERROR(INDEX('Monthly Matrix'!$I$4:$I$76,MATCH(LARGE('Monthly Matrix'!$AB$4:$AB$76,2),'Monthly Matrix'!$AB$4:$AB$76,0)),"") | I14: =IFERROR(INDEX('Monthly Matrix'!$N$4:$N$76,MATCH(LARGE('Monthly Matrix'!$AB$4:$AB$76,2),'Monthly Matrix'!$AB$4:$AB$76,0)),"") | J14: =IFERROR(INDEX('Monthly Matrix'!$P$4:$P$76,MATCH(LARGE('Monthly Matrix'!$AB$4:$AB$76,2),'Monthly Matrix'!$AB$4:$AB$76,0)),"") | K14: =IFERROR(INDEX('Monthly Matrix'!$AH$4:$AH$76,MATCH(LARGE('Monthly Matrix'!$AB$4:$AB$76,2),'Monthly Matrix'!$AB$4:$AB$76,0)),"") | L14: =IFERROR(INDEX('Monthly Matrix'!$AI$4:$AI$76,MATCH(LARGE('Monthly Matrix'!$AB$4:$AB$76,2),'Monthly Matrix'!$AB$4:$AB$76,0))/K14,"") | M14: =IFERROR(INDEX('Monthly Matrix'!$AF$4:$AF$76,MATCH(LARGE('Monthly Matrix'!$AB$4:$AB$76,2),'Monthly Matrix'!$AB$4:$AB$76,0)),"")
A15: 3 | B15: =IFERROR(INDEX('Monthly Matrix'!$B$4:$B$76,MATCH(LARGE('Monthly Matrix'!$AB$4:$AB$76,3),'Monthly Matrix'!$AB$4:$AB$76,0)),"") | C15: =IFERROR(INDEX('Monthly Matrix'!$C$4:$C$76,MATCH(LARGE('Monthly Matrix'!$AB$4:$AB$76,3),'Monthly Matrix'!$AB$4:$AB$76,0)),"") | D15: =IFERROR(INDEX('Monthly Matrix'!$E$4:$E$76,MATCH(LARGE('Monthly Matrix'!$AB$4:$AB$76,3),'Monthly Matrix'!$AB$4:$AB$76,0)),"") | E15: =IFERROR(INDEX('Monthly Matrix'!$T$4:$T$76,MATCH(LARGE('Monthly Matrix'!$AB$4:$AB$76,3),'Monthly Matrix'!$AB$4:$AB$76,0)),"") | F15: =IFERROR(INDEX('Monthly Matrix'!$V$4:$AA$76,MATCH(LARGE('Monthly Matrix'!$AB$4:$AB$76,3),'Monthly Matrix'!$AB$4:$AB$76,0)),"") | G15: =IFERROR(INDEX('Monthly Matrix'!$J$4:$J$76,MATCH(LARGE('Monthly Matrix'!$AB$4:$AB$76,3),'Monthly Matrix'!$AB$4:$AB$76,0)),"") | H15: =IFERROR(INDEX('Monthly Matrix'!$I$4:$I$76,MATCH(LARGE('Monthly Matrix'!$AB$4:$AB$76,3),'Monthly Matrix'!$AB$4:$AB$76,0)),"") | I15: =IFERROR(INDEX('Monthly Matrix'!$N$4:$N$76,MATCH(LARGE('Monthly Matrix'!$AB$4:$AB$76,3),'Monthly Matrix'!$AB$4:$AB$76,0)),"") | J15: =IFERROR(INDEX('Monthly Matrix'!$P$4:$P$76,MATCH(LARGE('Monthly Matrix'!$AB$4:$AB$76,3),'Monthly Matrix'!$AB$4:$AB$76,0)),"") | K15: =IFERROR(INDEX('Monthly Matrix'!$AH$4:$AH$76,MATCH(LARGE('Monthly Matrix'!$AB$4:$AB$76,3),'Monthly Matrix'!$AB$4:$AB$76,0)),"") | L15: =IFERROR(INDEX('Monthly Matrix'!$AI$4:$AI$76,MATCH(LARGE('Monthly Matrix'!$AB$4:$AB$76,3),'Monthly Matrix'!$AB$4:$AB$76,0))/K15,"") | M15: =IFERROR(INDEX('Monthly Matrix'!$AF$4:$AF$76,MATCH(LARGE('Monthly Matrix'!$AB$4:$AB$76,3),'Monthly Matrix'!$AB$4:$AB$76,0)),"")
A16: 4 | B16: =IFERROR(INDEX('Monthly Matrix'!$B$4:$B$76,MATCH(LARGE('Monthly Matrix'!$AB$4:$AB$76,4),'Monthly Matrix'!$AB$4:$AB$76,0)),"") | C16: =IFERROR(INDEX('Monthly Matrix'!$C$4:$C$76,MATCH(LARGE('Monthly Matrix'!$AB$4:$AB$76,4),'Monthly Matrix'!$AB$4:$AB$76,0)),"") | D16: =IFERROR(INDEX('Monthly Matrix'!$E$4:$E$76,MATCH(LARGE('Monthly Matrix'!$AB$4:$AB$76,4),'Monthly Matrix'!$AB$4:$AB$76,0)),"") | E16: =IFERROR(INDEX('Monthly Matrix'!$T$4:$T$76,MATCH(LARGE('Monthly Matrix'!$AB$4:$AB$76,4),'Monthly Matrix'!$AB$4:$AB$76,0)),"") | F16: =IFERROR(INDEX('Monthly Matrix'!$V$4:$AA$76,MATCH(LARGE('Monthly Matrix'!$AB$4:$AB$76,4),'Monthly Matrix'!$AB$4:$AB$76,0)),"") | G16: =IFERROR(INDEX('Monthly Matrix'!$J$4:$J$76,MATCH(LARGE('Monthly Matrix'!$AB$4:$AB$76,4),'Monthly Matrix'!$AB$4:$AB$76,0)),"") | H16: =IFERROR(INDEX('Monthly Matrix'!$I$4:$I$76,MATCH(LARGE('Monthly Matrix'!$AB$4:$AB$76,4),'Monthly Matrix'!$AB$4:$AB$76,0)),"") | I16: =IFERROR(INDEX('Monthly Matrix'!$N$4:$N$76,MATCH(LARGE('Monthly Matrix'!$AB$4:$AB$76,4),'Monthly Matrix'!$AB$4:$AB$76,0)),"") | J16: =IFERROR(INDEX('Monthly Matrix'!$P$4:$P$76,MATCH(LARGE('Monthly Matrix'!$AB$4:$AB$76,4),'Monthly Matrix'!$AB$4:$AB$76,0)),"") | K16: =IFERROR(INDEX('Monthly Matrix'!$AH$4:$AH$76,MATCH(LARGE('Monthly Matrix'!$AB$4:$AB$76,4),'Monthly Matrix'!$AB$4:$AB$76,0)),"") | L16: =IFERROR(INDEX('Monthly Matrix'!$AI$4:$AI$76,MATCH(LARGE('Monthly Matrix'!$AB$4:$AB$76,4),'Monthly Matrix'!$AB$4:$AB$76,0))/K16,"") | M16: =IFERROR(INDEX('Monthly Matrix'!$AF$4:$AF$76,MATCH(LARGE('Monthly Matrix'!$AB$4:$AB$76,4),'Monthly Matrix'!$AB$4:$AB$76,0)),"")
A17: 5 | B17: =IFERROR(INDEX('Monthly Matrix'!$B$4:$B$76,MATCH(LARGE('Monthly Matrix'!$AB$4:$AB$76,5),'Monthly Matrix'!$AB$4:$AB$76,0)),"") | C17: =IFERROR(INDEX('Monthly Matrix'!$C$4:$C$76,MATCH(LARGE('Monthly Matrix'!$AB$4:$AB$76,5),'Monthly Matrix'!$AB$4:$AB$76,0)),"") | D17: =IFERROR(INDEX('Monthly Matrix'!$E$4:$E$76,MATCH(LARGE('Monthly Matrix'!$AB$4:$AB$76,5),'Monthly Matrix'!$AB$4:$AB$76,0)),"") | E17: =IFERROR(INDEX('Monthly Matrix'!$T$4:$T$76,MATCH(LARGE('Monthly Matrix'!$AB$4:$AB$76,5),'Monthly Matrix'!$AB$4:$AB$76,0)),"") | F17: =IFERROR(INDEX('Monthly Matrix'!$V$4:$AA$76,MATCH(LARGE('Monthly Matrix'!$AB$4:$AB$76,5),'Monthly Matrix'!$AB$4:$AB$76,0)),"") | G17: =IFERROR(INDEX('Monthly Matrix'!$J$4:$J$76,MATCH(LARGE('Monthly Matrix'!$AB$4:$AB$76,5),'Monthly Matrix'!$AB$4:$AB$76,0)),"") | H17: =IFERROR(INDEX('Monthly Matrix'!$I$4:$I$76,MATCH(LARGE('Monthly Matrix'!$AB$4:$AB$76,5),'Monthly Matrix'!$AB$4:$AB$76,0)),"") | I17: =IFERROR(INDEX('Monthly Matrix'!$N$4:$N$76,MATCH(LARGE('Monthly Matrix'!$AB$4:$AB$76,5),'Monthly Matrix'!$AB$4:$AB$76,0)),"") | J17: =IFERROR(INDEX('Monthly Matrix'!$P$4:$P$76,MATCH(LARGE('Monthly Matrix'!$AB$4:$AB$76,5),'Monthly Matrix'!$AB$4:$AB$76,0)),"") | K17: =IFERROR(INDEX('Monthly Matrix'!$AH$4:$AH$76,MATCH(LARGE('Monthly Matrix'!$AB$4:$AB$76,5),'Monthly Matrix'!$AB$4:$AB$76,0)),"") | L17: =IFERROR(INDEX('Monthly Matrix'!$AI$4:$AI$76,MATCH(LARGE('Monthly Matrix'!$AB$4:$AB$76,5),'Monthly Matrix'!$AB$4:$AB$76,0))/K17,"") | M17: =IFERROR(INDEX('Monthly Matrix'!$AF$4:$AF$76,MATCH(LARGE('Monthly Matrix'!$AB$4:$AB$76,5),'Monthly Matrix'!$AB$4:$AB$76,0)),"")
A18: 6 | B18: =IFERROR(INDEX('Monthly Matrix'!$B$4:$B$76,MATCH(LARGE('Monthly Matrix'!$AB$4:$AB$76,6),'Monthly Matrix'!$AB$4:$AB$76,0)),"") | C18: =IFERROR(INDEX('Monthly Matrix'!$C$4:$C$76,MATCH(LARGE('Monthly Matrix'!$AB$4:$AB$76,6),'Monthly Matrix'!$AB$4:$AB$76,0)),"") | D18: =IFERROR(INDEX('Monthly Matrix'!$E$4:$E$76,MATCH(LARGE('Monthly Matrix'!$AB$4:$AB$76,6),'Monthly Matrix'!$AB$4:$AB$76,0)),"") | E18: =IFERROR(INDEX('Monthly Matrix'!$T$4:$T$76,MATCH(LARGE('Monthly Matrix'!$AB$4:$AB$76,6),'Monthly Matrix'!$AB$4:$AB$76,0)),"") | F18: =IFERROR(INDEX('Monthly Matrix'!$V$4:$AA$76,MATCH(LARGE('Monthly Matrix'!$AB$4:$AB$76,6),'Monthly Matrix'!$AB$4:$AB$76,0)),"") | G18: =IFERROR(INDEX('Monthly Matrix'!$J$4:$J$76,MATCH(LARGE('Monthly Matrix'!$AB$4:$AB$76,6),'Monthly Matrix'!$AB$4:$AB$76,0)),"") | H18: =IFERROR(INDEX('Monthly Matrix'!$I$4:$I$76,MATCH(LARGE('Monthly Matrix'!$AB$4:$AB$76,6),'Monthly Matrix'!$AB$4:$AB$76,0)),"") | I18: =IFERROR(INDEX('Monthly Matrix'!$N$4:$N$76,MATCH(LARGE('Monthly Matrix'!$AB$4:$AB$76,6),'Monthly Matrix'!$AB$4:$AB$76,0)),"") | J18: =IFERROR(INDEX('Monthly Matrix'!$P$4:$P$76,MATCH(LARGE('Monthly Matrix'!$AB$4:$AB$76,6),'Monthly Matrix'!$AB$4:$AB$76,0)),"") | K18: =IFERROR(INDEX('Monthly Matrix'!$AH$4:$AH$76,MATCH(LARGE('Monthly Matrix'!$AB$4:$AB$76,6),'Monthly Matrix'!$AB$4:$AB$76,0)),"") | L18: =IFERROR(INDEX('Monthly Matrix'!$AI$4:$AI$76,MATCH(LARGE('Monthly Matrix'!$AB$4:$AB$76,6),'Monthly Matrix'!$AB$4:$AB$76,0))/K18,"") | M18: =IFERROR(INDEX('Monthly Matrix'!$AF$4:$AF$76,MATCH(LARGE('Monthly Matrix'!$AB$4:$AB$76,6),'Monthly Matrix'!$AB$4:$AB$76,0)),"")
A19: 7 | B19: =IFERROR(INDEX('Monthly Matrix'!$B$4:$B$76,MATCH(LARGE('Monthly Matrix'!$AB$4:$AB$76,7),'Monthly Matrix'!$AB$4:$AB$76,0)),"") | C19: =IFERROR(INDEX('Monthly Matrix'!$C$4:$C$76,MATCH(LARGE('Monthly Matrix'!$AB$4:$AB$76,7),'Monthly Matrix'!$AB$4:$AB$76,0)),"") | D19: =IFERROR(INDEX('Monthly Matrix'!$E$4:$E$76,MATCH(LARGE('Monthly Matrix'!$AB$4:$AB$76,7),'Monthly Matrix'!$AB$4:$AB$76,0)),"") | E19: =IFERROR(INDEX('Monthly Matrix'!$T$4:$T$76,MATCH(LARGE('Monthly Matrix'!$AB$4:$AB$76,7),'Monthly Matrix'!$AB$4:$AB$76,0)),"") | F19: =IFERROR(INDEX('Monthly Matrix'!$V$4:$AA$76,MATCH(LARGE('Monthly Matrix'!$AB$4:$AB$76,7),'Monthly Matrix'!$AB$4:$AB$76,0)),"") | G19: =IFERROR(INDEX('Monthly Matrix'!$J$4:$J$76,MATCH(LARGE('Monthly Matrix'!$AB$4:$AB$76,7),'Monthly Matrix'!$AB$4:$AB$76,0)),"") | H19: =IFERROR(INDEX('Monthly Matrix'!$I$4:$I$76,MATCH(LARGE('Monthly Matrix'!$AB$4:$AB$76,7),'Monthly Matrix'!$AB$4:$AB$76,0)),"") | I19: =IFERROR(INDEX('Monthly Matrix'!$N$4:$N$76,MATCH(LARGE('Monthly Matrix'!$AB$4:$AB$76,7),'Monthly Matrix'!$AB$4:$AB$76,0)),"") | J19: =IFERROR(INDEX('Monthly Matrix'!$P$4:$P$76,MATCH(LARGE('Monthly Matrix'!$AB$4:$AB$76,7),'Monthly Matrix'!$AB$4:$AB$76,0)),"") | K19: =IFERROR(INDEX('Monthly Matrix'!$AH$4:$AH$76,MATCH(LARGE('Monthly Matrix'!$AB$4:$AB$76,7),'Monthly Matrix'!$AB$4:$AB$76,0)),"") | L19: =IFERROR(INDEX('Monthly Matrix'!$AI$4:$AI$76,MATCH(LARGE('Monthly Matrix'!$AB$4:$AB$76,7),'Monthly Matrix'!$AB$4:$AB$76,0))/K19,"") | M19: =IFERROR(INDEX('Monthly Matrix'!$AF$4:$AF$76,MATCH(LARGE('Monthly Matrix'!$AB$4:$AB$76,7),'Monthly Matrix'!$AB$4:$AB$76,0)),"")
A20: 8 | B20: =IFERROR(INDEX('Monthly Matrix'!$B$4:$B$76,MATCH(LARGE('Monthly Matrix'!$AB$4:$AB$76,8),'Monthly Matrix'!$AB$4:$AB$76,0)),"") | C20: =IFERROR(INDEX('Monthly Matrix'!$C$4:$C$76,MATCH(LARGE('Monthly Matrix'!$AB$4:$AB$76,8),'Monthly Matrix'!$AB$4:$AB$76,0)),"") | D20: =IFERROR(INDEX('Monthly Matrix'!$E$4:$E$76,MATCH(LARGE('Monthly Matrix'!$AB$4:$AB$76,8),'Monthly Matrix'!$AB$4:$AB$76,0)),"") | E20: =IFERROR(INDEX('Monthly Matrix'!$T$4:$T$76,MATCH(LARGE('Monthly Matrix'!$AB$4:$AB$76,8),'Monthly Matrix'!$AB$4:$AB$76,0)),"") | F20: =IFERROR(INDEX('Monthly Matrix'!$V$4:$AA$76,MATCH(LARGE('Monthly Matrix'!$AB$4:$AB$76,8),'Monthly Matrix'!$AB$4:$AB$76,0)),"") | G20: =IFERROR(INDEX('Monthly Matrix'!$J$4:$J$76,MATCH(LARGE('Monthly Matrix'!$AB$4:$AB$76,8),'Monthly Matrix'!$AB$4:$AB$76,0)),"") | H20: =IFERROR(INDEX('Monthly Matrix'!$I$4:$I$76,MATCH(LARGE('Monthly Matrix'!$AB$4:$AB$76,8),'Monthly Matrix'!$AB$4:$AB$76,0)),"") | I20: =IFERROR(INDEX('Monthly Matrix'!$N$4:$N$76,MATCH(LARGE('Monthly Matrix'!$AB$4:$AB$76,8),'Monthly Matrix'!$AB$4:$AB$76,0)),"") | J20: =IFERROR(INDEX('Monthly Matrix'!$P$4:$P$76,MATCH(LARGE('Monthly Matrix'!$AB$4:$AB$76,8),'Monthly Matrix'!$AB$4:$AB$76,0)),"") | K20: =IFERROR(INDEX('Monthly Matrix'!$AH$4:$AH$76,MATCH(LARGE('Monthly Matrix'!$AB$4:$AB$76,8),'Monthly Matrix'!$AB$4:$AB$76,0)),"") | L20: =IFERROR(INDEX('Monthly Matrix'!$AI$4:$AI$76,MATCH(LARGE('Monthly Matrix'!$AB$4:$AB$76,8),'Monthly Matrix'!$AB$4:$AB$76,0))/K20,"") | M20: =IFERROR(INDEX('Monthly Matrix'!$AF$4:$AF$76,MATCH(LARGE('Monthly Matrix'!$AB$4:$AB$76,8),'Monthly Matrix'!$AB$4:$AB$76,0)),"")
A21: 9 | B21: =IFERROR(INDEX('Monthly Matrix'!$B$4:$B$76,MATCH(LARGE('Monthly Matrix'!$AB$4:$AB$76,9),'Monthly Matrix'!$AB$4:$AB$76,0)),"") | C21: =IFERROR(INDEX('Monthly Matrix'!$C$4:$C$76,MATCH(LARGE('Monthly Matrix'!$AB$4:$AB$76,9),'Monthly Matrix'!$AB$4:$AB$76,0)),"") | D21: =IFERROR(INDEX('Monthly Matrix'!$E$4:$E$76,MATCH(LARGE('Monthly Matrix'!$AB$4:$AB$76,9),'Monthly Matrix'!$AB$4:$AB$76,0)),"") | E21: =IFERROR(INDEX('Monthly Matrix'!$T$4:$T$76,MATCH(LARGE('Monthly Matrix'!$AB$4:$AB$76,9),'Monthly Matrix'!$AB$4:$AB$76,0)),"") | F21: =IFERROR(INDEX('Monthly Matrix'!$V$4:$AA$76,MATCH(LARGE('Monthly Matrix'!$AB$4:$AB$76,9),'Monthly Matrix'!$AB$4:$AB$76,0)),"") | G21: =IFERROR(INDEX('Monthly Matrix'!$J$4:$J$76,MATCH(LARGE('Monthly Matrix'!$AB$4:$AB$76,9),'Monthly Matrix'!$AB$4:$AB$76,0)),"") | H21: =IFERROR(INDEX('Monthly Matrix'!$I$4:$I$76,MATCH(LARGE('Monthly Matrix'!$AB$4:$AB$76,9),'Monthly Matrix'!$AB$4:$AB$76,0)),"") | I21: =IFERROR(INDEX('Monthly Matrix'!$N$4:$N$76,MATCH(LARGE('Monthly Matrix'!$AB$4:$AB$76,9),'Monthly Matrix'!$AB$4:$AB$76,0)),"") | J21: =IFERROR(INDEX('Monthly Matrix'!$P$4:$P$76,MATCH(LARGE('Monthly Matrix'!$AB$4:$AB$76,9),'Monthly Matrix'!$AB$4:$AB$76,0)),"") | K21: =IFERROR(INDEX('Monthly Matrix'!$AH$4:$AH$76,MATCH(LARGE('Monthly Matrix'!$AB$4:$AB$76,9),'Monthly Matrix'!$AB$4:$AB$76,0)),"") | L21: =IFERROR(INDEX('Monthly Matrix'!$AI$4:$AI$76,MATCH(LARGE('Monthly Matrix'!$AB$4:$AB$76,9),'Monthly Matrix'!$AB$4:$AB$76,0))/K21,"") | M21: =IFERROR(INDEX('Monthly Matrix'!$AF$4:$AF$76,MATCH(LARGE('Monthly Matrix'!$AB$4:$AB$76,9),'Monthly Matrix'!$AB$4:$AB$76,0)),"")
A22: 10 | B22: =IFERROR(INDEX('Monthly Matrix'!$B$4:$B$76,MATCH(LARGE('Monthly Matrix'!$AB$4:$AB$76,10),'Monthly Matrix'!$AB$4:$AB$76,0)),"") | C22: =IFERROR(INDEX('Monthly Matrix'!$C$4:$C$76,MATCH(LARGE('Monthly Matrix'!$AB$4:$AB$76,10),'Monthly Matrix'!$AB$4:$AB$76,0)),"") | D22: =IFERROR(INDEX('Monthly Matrix'!$E$4:$E$76,MATCH(LARGE('Monthly Matrix'!$AB$4:$AB$76,10),'Monthly Matrix'!$AB$4:$AB$76,0)),"") | E22: =IFERROR(INDEX('Monthly Matrix'!$T$4:$T$76,MATCH(LARGE('Monthly Matrix'!$AB$4:$AB$76,10),'Monthly Matrix'!$AB$4:$AB$76,0)),"") | F22: =IFERROR(INDEX('Monthly Matrix'!$V$4:$AA$76,MATCH(LARGE('Monthly Matrix'!$AB$4:$AB$76,10),'Monthly Matrix'!$AB$4:$AB$76,0)),"") | G22: =IFERROR(INDEX('Monthly Matrix'!$J$4:$J$76,MATCH(LARGE('Monthly Matrix'!$AB$4:$AB$76,10),'Monthly Matrix'!$AB$4:$AB$76,0)),"") | H22: =IFERROR(INDEX('Monthly Matrix'!$I$4:$I$76,MATCH(LARGE('Monthly Matrix'!$AB$4:$AB$76,10),'Monthly Matrix'!$AB$4:$AB$76,0)),"") | I22: =IFERROR(INDEX('Monthly Matrix'!$N$4:$N$76,MATCH(LARGE('Monthly Matrix'!$AB$4:$AB$76,10),'Monthly Matrix'!$AB$4:$AB$76,0)),"") | J22: =IFERROR(INDEX('Monthly Matrix'!$P$4:$P$76,MATCH(LARGE('Monthly Matrix'!$AB$4:$AB$76,10),'Monthly Matrix'!$AB$4:$AB$76,0)),"") | K22: =IFERROR(INDEX('Monthly Matrix'!$AH$4:$AH$76,MATCH(LARGE('Monthly Matrix'!$AB$4:$AB$76,10),'Monthly Matrix'!$AB$4:$AB$76,0)),"") | L22: =IFERROR(INDEX('Monthly Matrix'!$AI$4:$AI$76,MATCH(LARGE('Monthly Matrix'!$AB$4:$AB$76,10),'Monthly Matrix'!$AB$4:$AB$76,0))/K22,"") | M22: =IFERROR(INDEX('Monthly Matrix'!$AF$4:$AF$76,MATCH(LARGE('Monthly Matrix'!$AB$4:$AB$76,10),'Monthly Matrix'!$AB$4:$AB$76,0)),"")
A24: PORTFOLIO AVERAGES - KEY METRICS
A25: Metric | B25: This Month | C25: Target | D25: Status
A26: Amber alerts - total vs target | B26: =SUM('Monthly Matrix'!J4:J76) | C26: =SUM('Monthly Matrix'!I4:I76) | D26: =IF(B26>=C26,"ON TARGET","BELOW TARGET")
A27: Skillko Compliance - portfolio avg % | B27: =IFERROR(ROUND(AVERAGEIF('Monthly Matrix'!N4:N76,">0"),1),0) | C27: 95 | D27: =IF(B27>=C27,"ON TARGET","BELOW TARGET")
A28: Post-Cut Quality - compliant pole rate % | B28: =IFERROR(ROUND(SUM('Monthly Matrix'!AD4:AD76)/SUM('Monthly Matrix'!AC4:AC76)*100,1),"-") | C28: 95 | D28: =IF(ISNUMBER(B28),IF(B28>=C28,"ON TARGET","BELOW TARGET"),"-")
A29: Post-Cut Quality - non-compliant poles total | B29: =SUM('Monthly Matrix'!P4:P76) | C29: 0 | D29: =IF(B29=0,"ON TARGET","BELOW TARGET")
A30: HIGH risk teams | B30: =COUNTIF('Monthly Matrix'!AA4:AA76,"HIGH") | C30: 0 | D30: =IF(B30=0,"ON TARGET","ACTION REQUIRED")
A31: Audit completion rate % | B31: =IFERROR(ROUND(COUNTIF('Audit Schedule'!J4:J76,"Completed")/MAX(1,COUNTA('Audit Schedule'!A4:A76))*100,1),"-") | C31: 100 | D31: =IF(ISNUMBER(B31),IF(B31>=80,"ON TARGET","BELOW TARGET"),"-")
A32: Portfolio avg composite score - this month | B32: =IFERROR(ROUND(SUMPRODUCT(('Monthly Matrix'!AA4:AA76<>"")*'Monthly Matrix'!T4:T76)/MAX(1,COUNTIF('Monthly Matrix'!AA4:AA76,"<>")),1),"-") | C32: > 3.25 (portfolio LOW risk) | D32: =IF(ISNUMBER(B32),IF(B32>3.25,"ON TARGET","BELOW TARGET"),"-")
A33: GOVERNANCE • HIGH risk: PM 3x site visits per week until LOW for 4 consecutive weeks • Improvement plans due within 5 working days of month-end score • Major events: immediate escalation - do not wait for month-end review
A37: TOP 10 LOWEST RISK TEAMS
A38: Rank | B38: Team | C38: Contract | D38: SOM | E38: Score | F38: RAG | G38: Amber Count | H38: Amber Target | I38: Skillko % | J38: Quality Fails | K38: Checks Assessed | L38: Compliant Checks | M38: Plan?
A39: 1 | B39: =IFERROR(INDEX('Monthly Matrix'!$B$4:$B$76,MATCH(SMALL('Monthly Matrix'!$AH$4:$AH$76,1),'Monthly Matrix'!$AH$4:$AH$76,0)),"") | C39: =IFERROR(INDEX('Monthly Matrix'!$C$4:$C$76,MATCH(SMALL('Monthly Matrix'!$AH$4:$AH$76,1),'Monthly Matrix'!$AH$4:$AH$76,0)),"") | D39: =IFERROR(INDEX('Monthly Matrix'!$E$4:$E$76,MATCH(SMALL('Monthly Matrix'!$AH$4:$AH$76,1),'Monthly Matrix'!$AH$4:$AH$76,0)),"") | E39: =IFERROR(INDEX('Monthly Matrix'!$T$4:$T$76,MATCH(SMALL('Monthly Matrix'!$AH$4:$AH$76,1),'Monthly Matrix'!$AH$4:$AH$76,0)),"") | F39: =IFERROR(INDEX('Monthly Matrix'!$V$4:$AA$76,MATCH(SMALL('Monthly Matrix'!$AH$4:$AH$76,1),'Monthly Matrix'!$AH$4:$AH$76,0)),"") | G39: =IFERROR(INDEX('Monthly Matrix'!$J$4:$J$76,MATCH(SMALL('Monthly Matrix'!$AH$4:$AH$76,1),'Monthly Matrix'!$AH$4:$AH$76,0)),"") | H39: =IFERROR(INDEX('Monthly Matrix'!$I$4:$I$76,MATCH(SMALL('Monthly Matrix'!$AH$4:$AH$76,1),'Monthly Matrix'!$AH$4:$AH$76,0)),"") | I39: =IFERROR(INDEX('Monthly Matrix'!$N$4:$N$76,MATCH(SMALL('Monthly Matrix'!$AH$4:$AH$76,1),'Monthly Matrix'!$AH$4:$AH$76,0)),"") | J39: =IFERROR(INDEX('Monthly Matrix'!$P$4:$P$76,MATCH(SMALL('Monthly Matrix'!$AH$4:$AH$76,1),'Monthly Matrix'!$AH$4:$AH$76,0)),"") | K39: =IFERROR(INDEX('Monthly Matrix'!$AH$4:$AH$76,MATCH(SMALL('Monthly Matrix'!$AH$4:$AH$76,1),'Monthly Matrix'!$AH$4:$AH$76,0)),"") | L39: =IFERROR(INDEX('Monthly Matrix'!$AI$4:$AI$76,MATCH(SMALL('Monthly Matrix'!$AH$4:$AH$76,1),'Monthly Matrix'!$AH$4:$AH$76,0))/K39,"") | M39: =IFERROR(INDEX('Monthly Matrix'!$AF$4:$AF$76,MATCH(SMALL('Monthly Matrix'!$AH$4:$AH$76,1),'Monthly Matrix'!$AH$4:$AH$76,0)),"")
A40: 2 | B40: =IFERROR(INDEX('Monthly Matrix'!$B$4:$B$76,MATCH(SMALL('Monthly Matrix'!$AH$4:$AH$76,2),'Monthly Matrix'!$AH$4:$AH$76,0)),"") | C40: =IFERROR(INDEX('Monthly Matrix'!$C$4:$C$76,MATCH(SMALL('Monthly Matrix'!$AH$4:$AH$76,2),'Monthly Matrix'!$AH$4:$AH$76,0)),"") | D40: =IFERROR(INDEX('Monthly Matrix'!$E$4:$E$76,MATCH(SMALL('Monthly Matrix'!$AH$4:$AH$76,2),'Monthly Matrix'!$AH$4:$AH$76,0)),"") | E40: =IFERROR(INDEX('Monthly Matrix'!$T$4:$T$76,MATCH(SMALL('Monthly Matrix'!$AH$4:$AH$76,2),'Monthly Matrix'!$AH$4:$AH$76,0)),"") | F40: =IFERROR(INDEX('Monthly Matrix'!$V$4:$AA$76,MATCH(SMALL('Monthly Matrix'!$AH$4:$AH$76,2),'Monthly Matrix'!$AH$4:$AH$76,0)),"") | G40: =IFERROR(INDEX('Monthly Matrix'!$J$4:$J$76,MATCH(SMALL('Monthly Matrix'!$AH$4:$AH$76,2),'Monthly Matrix'!$AH$4:$AH$76,0)),"") | H40: =IFERROR(INDEX('Monthly Matrix'!$I$4:$I$76,MATCH(SMALL('Monthly Matrix'!$AH$4:$AH$76,2),'Monthly Matrix'!$AH$4:$AH$76,0)),"") | I40: =IFERROR(INDEX('Monthly Matrix'!$N$4:$N$76,MATCH(SMALL('Monthly Matrix'!$AH$4:$AH$76,2),'Monthly Matrix'!$AH$4:$AH$76,0)),"") | J40: =IFERROR(INDEX('Monthly Matrix'!$P$4:$P$76,MATCH(SMALL('Monthly Matrix'!$AH$4:$AH$76,2),'Monthly Matrix'!$AH$4:$AH$76,0)),"") | K40: =IFERROR(INDEX('Monthly Matrix'!$AH$4:$AH$76,MATCH(SMALL('Monthly Matrix'!$AH$4:$AH$76,2),'Monthly Matrix'!$AH$4:$AH$76,0)),"") | L40: =IFERROR(INDEX('Monthly Matrix'!$AI$4:$AI$76,MATCH(SMALL('Monthly Matrix'!$AH$4:$AH$76,2),'Monthly Matrix'!$AH$4:$AH$76,0))/K40,"") | M40: =IFERROR(INDEX('Monthly Matrix'!$AF$4:$AF$76,MATCH(SMALL('Monthly Matrix'!$AH$4:$AH$76,2),'Monthly Matrix'!$AH$4:$AH$76,0)),"")
A41: 3 | B41: =IFERROR(INDEX('Monthly Matrix'!$B$4:$B$76,MATCH(SMALL('Monthly Matrix'!$AH$4:$AH$76,3),'Monthly Matrix'!$AH$4:$AH$76,0)),"") | C41: =IFERROR(INDEX('Monthly Matrix'!$C$4:$C$76,MATCH(SMALL('Monthly Matrix'!$AH$4:$AH$76,3),'Monthly Matrix'!$AH$4:$AH$76,0)),"") | D41: =IFERROR(INDEX('Monthly Matrix'!$E$4:$E$76,MATCH(SMALL('Monthly Matrix'!$AH$4:$AH$76,3),'Monthly Matrix'!$AH$4:$AH$76,0)),"") | E41: =IFERROR(INDEX('Monthly Matrix'!$T$4:$T$76,MATCH(SMALL('Monthly Matrix'!$AH$4:$AH$76,3),'Monthly Matrix'!$AH$4:$AH$76,0)),"") | F41: =IFERROR(INDEX('Monthly Matrix'!$V$4:$AA$76,MATCH(SMALL('Monthly Matrix'!$AH$4:$AH$76,3),'Monthly Matrix'!$AH$4:$AH$76,0)),"") | G41: =IFERROR(INDEX('Monthly Matrix'!$J$4:$J$76,MATCH(SMALL('Monthly Matrix'!$AH$4:$AH$76,3),'Monthly Matrix'!$AH$4:$AH$76,0)),"") | H41: =IFERROR(INDEX('Monthly Matrix'!$I$4:$I$76,MATCH(SMALL('Monthly Matrix'!$AH$4:$AH$76,3),'Monthly Matrix'!$AH$4:$AH$76,0)),"") | I41: =IFERROR(INDEX('Monthly Matrix'!$N$4:$N$76,MATCH(SMALL('Monthly Matrix'!$AH$4:$AH$76,3),'Monthly Matrix'!$AH$4:$AH$76,0)),"") | J41: =IFERROR(INDEX('Monthly Matrix'!$P$4:$P$76,MATCH(SMALL('Monthly Matrix'!$AH$4:$AH$76,3),'Monthly Matrix'!$AH$4:$AH$76,0)),"") | K41: =IFERROR(INDEX('Monthly Matrix'!$AH$4:$AH$76,MATCH(SMALL('Monthly Matrix'!$AH$4:$AH$76,3),'Monthly Matrix'!$AH$4:$AH$76,0)),"") | L41: =IFERROR(INDEX('Monthly Matrix'!$AI$4:$AI$76,MATCH(SMALL('Monthly Matrix'!$AH$4:$AH$76,3),'Monthly Matrix'!$AH$4:$AH$76,0))/K41,"") | M41: =IFERROR(INDEX('Monthly Matrix'!$AF$4:$AF$76,MATCH(SMALL('Monthly Matrix'!$AH$4:$AH$76,3),'Monthly Matrix'!$AH$4:$AH$76,0)),"")
A42: 4 | B42: =IFERROR(INDEX('Monthly Matrix'!$B$4:$B$76,MATCH(SMALL('Monthly Matrix'!$AH$4:$AH$76,4),'Monthly Matrix'!$AH$4:$AH$76,0)),"") | C42: =IFERROR(INDEX('Monthly Matrix'!$C$4:$C$76,MATCH(SMALL('Monthly Matrix'!$AH$4:$AH$76,4),'Monthly Matrix'!$AH$4:$AH$76,0)),"") | D42: =IFERROR(INDEX('Monthly Matrix'!$E$4:$E$76,MATCH(SMALL('Monthly Matrix'!$AH$4:$AH$76,4),'Monthly Matrix'!$AH$4:$AH$76,0)),"") | E42: =IFERROR(INDEX('Monthly Matrix'!$T$4:$T$76,MATCH(SMALL('Monthly Matrix'!$AH$4:$AH$76,4),'Monthly Matrix'!$AH$4:$AH$76,0)),"") | F42: =IFERROR(INDEX('Monthly Matrix'!$V$4:$AA$76,MATCH(SMALL('Monthly Matrix'!$AH$4:$AH$76,4),'Monthly Matrix'!$AH$4:$AH$76,0)),"") | G42: =IFERROR(INDEX('Monthly Matrix'!$J$4:$J$76,MATCH(SMALL('Monthly Matrix'!$AH$4:$AH$76,4),'Monthly Matrix'!$AH$4:$AH$76,0)),"") | H42: =IFERROR(INDEX('Monthly Matrix'!$I$4:$I$76,MATCH(SMALL('Monthly Matrix'!$AH$4:$AH$76,4),'Monthly Matrix'!$AH$4:$AH$76,0)),"") | I42: =IFERROR(INDEX('Monthly Matrix'!$N$4:$N$76,MATCH(SMALL('Monthly Matrix'!$AH$4:$AH$76,4),'Monthly Matrix'!$AH$4:$AH$76,0)),"") | J42: =IFERROR(INDEX('Monthly Matrix'!$P$4:$P$76,MATCH(SMALL('Monthly Matrix'!$AH$4:$AH$76,4),'Monthly Matrix'!$AH$4:$AH$76,0)),"") | K42: =IFERROR(INDEX('Monthly Matrix'!$AH$4:$AH$76,MATCH(SMALL('Monthly Matrix'!$AH$4:$AH$76,4),'Monthly Matrix'!$AH$4:$AH$76,0)),"") | L42: =IFERROR(INDEX('Monthly Matrix'!$AI$4:$AI$76,MATCH(SMALL('Monthly Matrix'!$AH$4:$AH$76,4),'Monthly Matrix'!$AH$4:$AH$76,0))/K42,"") | M42: =IFERROR(INDEX('Monthly Matrix'!$AF$4:$AF$76,MATCH(SMALL('Monthly Matrix'!$AH$4:$AH$76,4),'Monthly Matrix'!$AH$4:$AH$76,0)),"")
A43: 5 | B43: =IFERROR(INDEX('Monthly Matrix'!$B$4:$B$76,MATCH(SMALL('Monthly Matrix'!$AH$4:$AH$76,5),'Monthly Matrix'!$AH$4:$AH$76,0)),"") | C43: =IFERROR(INDEX('Monthly Matrix'!$C$4:$C$76,MATCH(SMALL('Monthly Matrix'!$AH$4:$AH$76,5),'Monthly Matrix'!$AH$4:$AH$76,0)),"") | D43: =IFERROR(INDEX('Monthly Matrix'!$E$4:$E$76,MATCH(SMALL('Monthly Matrix'!$AH$4:$AH$76,5),'Monthly Matrix'!$AH$4:$AH$76,0)),"") | E43: =IFERROR(INDEX('Monthly Matrix'!$T$4:$T$76,MATCH(SMALL('Monthly Matrix'!$AH$4:$AH$76,5),'Monthly Matrix'!$AH$4:$AH$76,0)),"") | F43: =IFERROR(INDEX('Monthly Matrix'!$V$4:$AA$76,MATCH(SMALL('Monthly Matrix'!$AH$4:$AH$76,5),'Monthly Matrix'!$AH$4:$AH$76,0)),"") | G43: =IFERROR(INDEX('Monthly Matrix'!$J$4:$J$76,MATCH(SMALL('Monthly Matrix'!$AH$4:$AH$76,5),'Monthly Matrix'!$AH$4:$AH$76,0)),"") | H43: =IFERROR(INDEX('Monthly Matrix'!$I$4:$I$76,MATCH(SMALL('Monthly Matrix'!$AH$4:$AH$76,5),'Monthly Matrix'!$AH$4:$AH$76,0)),"") | I43: =IFERROR(INDEX('Monthly Matrix'!$N$4:$N$76,MATCH(SMALL('Monthly Matrix'!$AH$4:$AH$76,5),'Monthly Matrix'!$AH$4:$AH$76,0)),"") | J43: =IFERROR(INDEX('Monthly Matrix'!$P$4:$P$76,MATCH(SMALL('Monthly Matrix'!$AH$4:$AH$76,5),'Monthly Matrix'!$AH$4:$AH$76,0)),"") | K43: =IFERROR(INDEX('Monthly Matrix'!$AH$4:$AH$76,MATCH(SMALL('Monthly Matrix'!$AH$4:$AH$76,5),'Monthly Matrix'!$AH$4:$AH$76,0)),"") | L43: =IFERROR(INDEX('Monthly Matrix'!$AI$4:$AI$76,MATCH(SMALL('Monthly Matrix'!$AH$4:$AH$76,5),'Monthly Matrix'!$AH$4:$AH$76,0))/K43,"") | M43: =IFERROR(INDEX('Monthly Matrix'!$AF$4:$AF$76,MATCH(SMALL('Monthly Matrix'!$AH$4:$AH$76,5),'Monthly Matrix'!$AH$4:$AH$76,0)),"")
A44: 6 | B44: =IFERROR(INDEX('Monthly Matrix'!$B$4:$B$76,MATCH(SMALL('Monthly Matrix'!$AH$4:$AH$76,6),'Monthly Matrix'!$AH$4:$AH$76,0)),"") | C44: =IFERROR(INDEX('Monthly Matrix'!$C$4:$C$76,MATCH(SMALL('Monthly Matrix'!$AH$4:$AH$76,6),'Monthly Matrix'!$AH$4:$AH$76,0)),"") | D44: =IFERROR(INDEX('Monthly Matrix'!$E$4:$E$76,MATCH(SMALL('Monthly Matrix'!$AH$4:$AH$76,6),'Monthly Matrix'!$AH$4:$AH$76,0)),"") | E44: =IFERROR(INDEX('Monthly Matrix'!$T$4:$T$76,MATCH(SMALL('Monthly Matrix'!$AH$4:$AH$76,6),'Monthly Matrix'!$AH$4:$AH$76,0)),"") | F44: =IFERROR(INDEX('Monthly Matrix'!$V$4:$AA$76,MATCH(SMALL('Monthly Matrix'!$AH$4:$AH$76,6),'Monthly Matrix'!$AH$4:$AH$76,0)),"") | G44: =IFERROR(INDEX('Monthly Matrix'!$J$4:$J$76,MATCH(SMALL('Monthly Matrix'!$AH$4:$AH$76,6),'Monthly Matrix'!$AH$4:$AH$76,0)),"") | H44: =IFERROR(INDEX('Monthly Matrix'!$I$4:$I$76,MATCH(SMALL('Monthly Matrix'!$AH$4:$AH$76,6),'Monthly Matrix'!$AH$4:$AH$76,0)),"") | I44: =IFERROR(INDEX('Monthly Matrix'!$N$4:$N$76,MATCH(SMALL('Monthly Matrix'!$AH$4:$AH$76,6),'Monthly Matrix'!$AH$4:$AH$76,0)),"") | J44: =IFERROR(INDEX('Monthly Matrix'!$P$4:$P$76,MATCH(SMALL('Monthly Matrix'!$AH$4:$AH$76,6),'Monthly Matrix'!$AH$4:$AH$76,0)),"") | K44: =IFERROR(INDEX('Monthly Matrix'!$AH$4:$AH$76,MATCH(SMALL('Monthly Matrix'!$AH$4:$AH$76,6),'Monthly Matrix'!$AH$4:$AH$76,0)),"") | L44: =IFERROR(INDEX('Monthly Matrix'!$AI$4:$AI$76,MATCH(SMALL('Monthly Matrix'!$AH$4:$AH$76,6),'Monthly Matrix'!$AH$4:$AH$76,0))/K44,"") | M44: =IFERROR(INDEX('Monthly Matrix'!$AF$4:$AF$76,MATCH(SMALL('Monthly Matrix'!$AH$4:$AH$76,6),'Monthly Matrix'!$AH$4:$AH$76,0)),"")
A45: 7 | B45: =IFERROR(INDEX('Monthly Matrix'!$B$4:$B$76,MATCH(SMALL('Monthly Matrix'!$AH$4:$AH$76,7),'Monthly Matrix'!$AH$4:$AH$76,0)),"") | C45: =IFERROR(INDEX('Monthly Matrix'!$C$4:$C$76,MATCH(SMALL('Monthly Matrix'!$AH$4:$AH$76,7),'Monthly Matrix'!$AH$4:$AH$76,0)),"") | D45: =IFERROR(INDEX('Monthly Matrix'!$E$4:$E$76,MATCH(SMALL('Monthly Matrix'!$AH$4:$AH$76,7),'Monthly Matrix'!$AH$4:$AH$76,0)),"") | E45: =IFERROR(INDEX('Monthly Matrix'!$T$4:$T$76,MATCH(SMALL('Monthly Matrix'!$AH$4:$AH$76,7),'Monthly Matrix'!$AH$4:$AH$76,0)),"") | F45: =IFERROR(INDEX('Monthly Matrix'!$V$4:$AA$76,MATCH(SMALL('Monthly Matrix'!$AH$4:$AH$76,7),'Monthly Matrix'!$AH$4:$AH$76,0)),"") | G45: =IFERROR(INDEX('Monthly Matrix'!$J$4:$J$76,MATCH(SMALL('Monthly Matrix'!$AH$4:$AH$76,7),'Monthly Matrix'!$AH$4:$AH$76,0)),"") | H45: =IFERROR(INDEX('Monthly Matrix'!$I$4:$I$76,MATCH(SMALL('Monthly Matrix'!$AH$4:$AH$76,7),'Monthly Matrix'!$AH$4:$AH$76,0)),"") | I45: =IFERROR(INDEX('Monthly Matrix'!$N$4:$N$76,MATCH(SMALL('Monthly Matrix'!$AH$4:$AH$76,7),'Monthly Matrix'!$AH$4:$AH$76,0)),"") | J45: =IFERROR(INDEX('Monthly Matrix'!$P$4:$P$76,MATCH(SMALL('Monthly Matrix'!$AH$4:$AH$76,7),'Monthly Matrix'!$AH$4:$AH$76,0)),"") | K45: =IFERROR(INDEX('Monthly Matrix'!$AH$4:$AH$76,MATCH(SMALL('Monthly Matrix'!$AH$4:$AH$76,7),'Monthly Matrix'!$AH$4:$AH$76,0)),"") | L45: =IFERROR(INDEX('Monthly Matrix'!$AI$4:$AI$76,MATCH(SMALL('Monthly Matrix'!$AH$4:$AH$76,7),'Monthly Matrix'!$AH$4:$AH$76,0))/K45,"") | M45: =IFERROR(INDEX('Monthly Matrix'!$AF$4:$AF$76,MATCH(SMALL('Monthly Matrix'!$AH$4:$AH$76,7),'Monthly Matrix'!$AH$4:$AH$76,0)),"")
A46: 8 | B46: =IFERROR(INDEX('Monthly Matrix'!$B$4:$B$76,MATCH(SMALL('Monthly Matrix'!$AH$4:$AH$76,8),'Monthly Matrix'!$AH$4:$AH$76,0)),"") | C46: =IFERROR(INDEX('Monthly Matrix'!$C$4:$C$76,MATCH(SMALL('Monthly Matrix'!$AH$4:$AH$76,8),'Monthly Matrix'!$AH$4:$AH$76,0)),"") | D46: =IFERROR(INDEX('Monthly Matrix'!$E$4:$E$76,MATCH(SMALL('Monthly Matrix'!$AH$4:$AH$76,8),'Monthly Matrix'!$AH$4:$AH$76,0)),"") | E46: =IFERROR(INDEX('Monthly Matrix'!$T$4:$T$76,MATCH(SMALL('Monthly Matrix'!$AH$4:$AH$76,8),'Monthly Matrix'!$AH$4:$AH$76,0)),"") | F46: =IFERROR(INDEX('Monthly Matrix'!$V$4:$AA$76,MATCH(SMALL('Monthly Matrix'!$AH$4:$AH$76,8),'Monthly Matrix'!$AH$4:$AH$76,0)),"") | G46: =IFERROR(INDEX('Monthly Matrix'!$J$4:$J$76,MATCH(SMALL('Monthly Matrix'!$AH$4:$AH$76,8),'Monthly Matrix'!$AH$4:$AH$76,0)),"") | H46: =IFERROR(INDEX('Monthly Matrix'!$I$4:$I$76,MATCH(SMALL('Monthly Matrix'!$AH$4:$AH$76,8),'Monthly Matrix'!$AH$4:$AH$76,0)),"") | I46: =IFERROR(INDEX('Monthly Matrix'!$N$4:$N$76,MATCH(SMALL('Monthly Matrix'!$AH$4:$AH$76,8),'Monthly Matrix'!$AH$4:$AH$76,0)),"") | J46: =IFERROR(INDEX('Monthly Matrix'!$P$4:$P$76,MATCH(SMALL('Monthly Matrix'!$AH$4:$AH$76,8),'Monthly Matrix'!$AH$4:$AH$76,0)),"") | K46: =IFERROR(INDEX('Monthly Matrix'!$AH$4:$AH$76,MATCH(SMALL('Monthly Matrix'!$AH$4:$AH$76,8),'Monthly Matrix'!$AH$4:$AH$76,0)),"") | L46: =IFERROR(INDEX('Monthly Matrix'!$AI$4:$AI$76,MATCH(SMALL('Monthly Matrix'!$AH$4:$AH$76,8),'Monthly Matrix'!$AH$4:$AH$76,0))/K46,"") | M46: =IFERROR(INDEX('Monthly Matrix'!$AF$4:$AF$76,MATCH(SMALL('Monthly Matrix'!$AH$4:$AH$76,8),'Monthly Matrix'!$AH$4:$AH$76,0)),"")
...

Sheet Field Teams
A1: FIELD TEAM MASTER LIST | L1: NEW TEAM CHECKER - auto-updates when Skillko data is pasted
A2: Master list — drives Monthly Matrix, Audit Schedule, Action Log and Dashboard automatically. Add new teams at the bottom. Use the Status dropdown (col I) to set Active or Inactive. Inactive teams are excluded from all scoring, rankings and counts. Do not delete rows. | L2: Teams found in Skillko export but NOT in master list are highlighted amber. Add them manually to the master list below (cols A–I) then set Status = Active.
A3: NOD = Sponsor Manager | SOM = Sponsor | CM = Contract Manager | PM = Project Manager | Operative Count auto-calculates from Data - Skillko tab | Status dropdown: Active / Inactive only | L3: Only team-level rows are shown (Job Role = Total, excluding company-named rows). Refresh by re-pasting Skillko data.
A4: Team ID | B4: Field Team Name | C4: Contract | D4: NOD | E4: SOM | F4: CM | G4: PM | H4: Operative Count (auto) | I4: Status | L4: Field Team Name (from Skillko) | M4: In Master List? | N4: Contract (Operating Unit)
A5: FT-001 | B5: Kingfisher Tree Services Ltd | C5: ESB - Utility Arboriculture | D5: Donovan Gosher | E5: Jake Bolwell | H5: =IFERROR(SUMPRODUCT(('Data - Skillko'!I$5:I$1547=B5)*('Data - Skillko'!D$5:D$1547="Total")*('Data - Skillko'!C$5:C$1547<>"Total")*('Data - Skillko'!C$5:C$1547<>"")*(NOT(ISNUMBER(SEARCH(B5,'Data - Skillko'!C$5:C$1547))))),0) | I5: Active | L5: Note: requires Excel 365 for UNIQUE and FILTER functions. If formula errors appear in L6, these functions are not available on this version.
A6: FT-002 | B6: WRS Tree Services Ltd | C6: Utility Arboriculture | D6: David Damm | E6: Mike Jackson | H6: =IFERROR(SUMPRODUCT(('Data - Skillko'!I$5:I$1547=B6)*('Data - Skillko'!D$5:D$1547="Total")*('Data - Skillko'!C$5:C$1547<>"Total")*('Data - Skillko'!C$5:C$1547<>"")*(NOT(ISNUMBER(SEARCH(B6,'Data - Skillko'!C$5:C$1547))))),0) | I6: Active | L6: No new Skillko teams missing from master list in current paste
A7: FT-003 | B7: Ashdown Tree Limited | C7: Utility Arboriculture | D7: Donovan Gosher | E7: Barry Bright | H7: =IFERROR(SUMPRODUCT(('Data - Skillko'!I$5:I$1547=B7)*('Data - Skillko'!D$5:D$1547="Total")*('Data - Skillko'!C$5:C$1547<>"Total")*('Data - Skillko'!C$5:C$1547<>"")*(NOT(ISNUMBER(SEARCH(B7,'Data - Skillko'!C$5:C$1547))))),0) | I7: Active
A8: FT-004 | B8: Austin Tree Care LTD | C8: Utility Arboriculture | D8: Donovan Gosher | E8: Barry Bright | H8: =IFERROR(SUMPRODUCT(('Data - Skillko'!I$5:I$1547=B8)*('Data - Skillko'!D$5:D$1547="Total")*('Data - Skillko'!C$5:C$1547<>"Total")*('Data - Skillko'!C$5:C$1547<>"")*(NOT(ISNUMBER(SEARCH(B8,'Data - Skillko'!C$5:C$1547))))),0) | I8: Active
A9: FT-005 | B9: D & R Landscapes | C9: Utility Arboriculture | D9: Donovan Gosher | E9: Barry Bright | H9: =IFERROR(SUMPRODUCT(('Data - Skillko'!I$5:I$1547=B9)*('Data - Skillko'!D$5:D$1547="Total")*('Data - Skillko'!C$5:C$1547<>"Total")*('Data - Skillko'!C$5:C$1547<>"")*(NOT(ISNUMBER(SEARCH(B9,'Data - Skillko'!C$5:C$1547))))),0) | I9: Active
A10: FT-006 | B10: Eastwoodbury Tree Services Ltd | C10: Utility Arboriculture | D10: Donovan Gosher | E10: Barry Bright | H10: =IFERROR(SUMPRODUCT(('Data - Skillko'!I$5:I$1547=B10)*('Data - Skillko'!D$5:D$1547="Total")*('Data - Skillko'!C$5:C$1547<>"Total")*('Data - Skillko'!C$5:C$1547<>"")*(NOT(ISNUMBER(SEARCH(B10,'Data - Skillko'!C$5:C$1547))))),0) | I10: Active
A11: FT-007 | B11: Green Net Eco Ltd | C11: Utility Arboriculture | D11: Donovan Gosher | E11: Barry Bright | H11: =IFERROR(SUMPRODUCT(('Data - Skillko'!I$5:I$1547=B11)*('Data - Skillko'!D$5:D$1547="Total")*('Data - Skillko'!C$5:C$1547<>"Total")*('Data - Skillko'!C$5:C$1547<>"")*(NOT(ISNUMBER(SEARCH(B11,'Data - Skillko'!C$5:C$1547))))),0) | I11: Active
A12: FT-008 | B12: Hope Ground and Tree Care | C12: Utility Arboriculture | D12: Donovan Gosher | E12: Barry Bright | H12: =IFERROR(SUMPRODUCT(('Data - Skillko'!I$5:I$1547=B12)*('Data - Skillko'!D$5:D$1547="Total")*('Data - Skillko'!C$5:C$1547<>"Total")*('Data - Skillko'!C$5:C$1547<>"")*(NOT(ISNUMBER(SEARCH(B12,'Data - Skillko'!C$5:C$1547))))),0) | I12: Active
A13: FT-009 | B13: M G Tree Surgery Ltd | C13: Utility Arboriculture | D13: Donovan Gosher | E13: Barry Bright | H13: =IFERROR(SUMPRODUCT(('Data - Skillko'!I$5:I$1547=B13)*('Data - Skillko'!D$5:D$1547="Total")*('Data - Skillko'!C$5:C$1547<>"Total")*('Data - Skillko'!C$5:C$1547<>"")*(NOT(ISNUMBER(SEARCH(B13,'Data - Skillko'!C$5:C$1547))))),0) | I13: Active
A14: FT-010 | B14: MAC Tree Surgery and Fencing Ltd | C14: Utility Arboriculture | D14: Donovan Gosher | E14: Barry Bright | H14: =IFERROR(SUMPRODUCT(('Data - Skillko'!I$5:I$1547=B14)*('Data - Skillko'!D$5:D$1547="Total")*('Data - Skillko'!C$5:C$1547<>"Total")*('Data - Skillko'!C$5:C$1547<>"")*(NOT(ISNUMBER(SEARCH(B14,'Data - Skillko'!C$5:C$1547))))),0) | I14: Active
A15: FT-011 | B15: Optimum Tree Services | C15: Utility Arboriculture | D15: Donovan Gosher | E15: Barry Bright | H15: =IFERROR(SUMPRODUCT(('Data - Skillko'!I$5:I$1547=B15)*('Data - Skillko'!D$5:D$1547="Total")*('Data - Skillko'!C$5:C$1547<>"Total")*('Data - Skillko'!C$5:C$1547<>"")*(NOT(ISNUMBER(SEARCH(B15,'Data - Skillko'!C$5:C$1547))))),0) | I15: Active
A16: FT-012 | B16: S6 Tree Specialists Ltd | C16: Utility Arboriculture | D16: Donovan Gosher | E16: Barry Bright | H16: =IFERROR(SUMPRODUCT(('Data - Skillko'!I$5:I$1547=B16)*('Data - Skillko'!D$5:D$1547="Total")*('Data - Skillko'!C$5:C$1547<>"Total")*('Data - Skillko'!C$5:C$1547<>"")*(NOT(ISNUMBER(SEARCH(B16,'Data - Skillko'!C$5:C$1547))))),0) | I16: Active
A17: FT-013 | B17: Tree Tech Suffolk Ltd | C17: Utility Arboriculture | D17: Donovan Gosher | E17: Barry Bright | H17: =IFERROR(SUMPRODUCT(('Data - Skillko'!I$5:I$1547=B17)*('Data - Skillko'!D$5:D$1547="Total")*('Data - Skillko'!C$5:C$1547<>"Total")*('Data - Skillko'!C$5:C$1547<>"")*(NOT(ISNUMBER(SEARCH(B17,'Data - Skillko'!C$5:C$1547))))),0) | I17: Active
A18: FT-014 | B18: Tree Tops Arborist | C18: Utility Arboriculture | D18: Donovan Gosher | E18: Barry Bright | H18: =IFERROR(SUMPRODUCT(('Data - Skillko'!I$5:I$1547=B18)*('Data - Skillko'!D$5:D$1547="Total")*('Data - Skillko'!C$5:C$1547<>"Total")*('Data - Skillko'!C$5:C$1547<>"")*(NOT(ISNUMBER(SEARCH(B18,'Data - Skillko'!C$5:C$1547))))),0) | I18: Active
... A77: FT-073 | B77: Wootton Forestry & Powerline Services Ltd | C77: Utility Arboriculture | D77: Paul Shaw | E77: David Damm | H77: =IFERROR(SUMPRODUCT(('Data - Skillko'!I$5:I$1547=B77)*('Data - Skillko'!D$5:D$1547="Total")*('Data - Skillko'!C$5:C$1547<>"Total")*('Data - Skillko'!C$5:C$1547<>"")*(NOT(ISNUMBER(SEARCH(B77,'Data - Skillko'!C$5:C$1547))))),0) | I77: Active
I78: Active
I79: Active
I80: Active
I81: Active
I82: Active
I83: Active
I84: Active
I85: Active
I86: Active
I87: Active
I88: Active
I89: Active
... I204: Active

Sheet Settings
A1: FIELD TEAM RISK MATRIX - SETTINGS & WEIGHTS
A2: Adjust weights and thresholds here — all other sheets update automatically. Do not modify metric formulas directly. Weights: Amber=18, Red Alerts=6, Skillko=8, Quality=7 (total=39 — scores now 1–5 per metric). Thresholds: HIGH ≤2.75, MEDIUM ≤3.24, LOW ≥3.25. Amber floor: teams scoring ≤2.0 on amber metric are auto-rated HIGH regardless of composite.
A4: METRIC WEIGHTS & SCORING - adjust Weight column only
A5: Metric | B5: Target | C5: Direction | D5: Weight (1-10) | E5: Scoring Logic | F5: Source
A6: Amber Alert Count | B6: 2 per person per month | C6: Low amber count = HIGH risk | D6: 18 | E6: Score = MAX(0,(target-actual)/target×10). Zero ambers = score 10. | F6: HSQE Tracker - Impact = Opportunity, DE/FT Name
A7: Red Alerts - Minor (G2) | B7: 0 | C7: Any red alerts = HIGH risk signal | D7: 6 | E7: Red Alert Score = MAX(Minor sub-score, Moderate/Major sub-score). Minor: each event = +0.8 above baseline 1, capped at 5. Moderate/Major: each event = +2 above baseline 1, capped at 5. Score = MAX(MIN(5, minor×0.8+1), MIN(5, mod_maj×2+1)). Major event also forces AUTO HIGH via override regardless of score. | F7: HSQE Events export - Impact = Minor | Moderate | Major, DE/FT Name
A8: Red Alerts - Moderate/Major (G3+) | B8: 0 | C8: Folded into Red Alert Score above | D8: 0 | E8: Count only - scoring handled by Red Alert Score in row 7. | F8: HSQE Events export - Impact = Moderate | Major, DE/FT Name
A9: Major event override | B9: 0 | C9: Any Major = AUTO HIGH | D9: 0 | E9: Any Major impact event forces team to HIGH regardless of composite score. | F9: HSQE Tracker 2 CSV - Impact = Major, DE/FT Name
A10: Skillko Compliance | B10: 95% | C10: Low % = HIGH risk | D10: 8 | E10: Score = (1 − actual%) × 4 + 1, range 1–5. E.g. 70% compliance = score 2.2. | F10: Skillko export - team summary rows, Compliance column
D11: 0
A12: Post-Cut Quality - defect rate | B12: 0% defect rate per month | C12: High defect rate = HIGH risk | D12: 7 | E12: Score = (non-compliant poles / total poles assessed) × 4 + 1, range 1–5, capped at 5. If no poles assessed this month, score = 0 (no data = no penalty). Uses rate not count, so team workload does not inflate risk. | F12: Post-cut quality export - FT On Site, Completed, Summary of Works
A13: Site Safety Visit (SSV) | D13: 10 | E13: Score based on Overall Result of SafetyCulture audits in rolling 90-day window. High Standards=4, Compliant=3, Minor NC with 1 finding=2, Minor NC with 2+ findings=1. 5 stars requires 2+ visits all returning High Standards. 1 visit High Standards = 4 stars maximum. No visits in window = 3 (neutral). | F13: SafetyCulture SSV export — Data - SSV tab
A14: Total Weight (active metrics) | D14: =D6+D7+D10+D12+D13
A15: Close-out Rate
A16: RISK THRESHOLDS
A17: Band | B17: Score Range | C17: RAG | D17: PM Visit Cadence | E17: Plan Required? | F17: Notes
A18: LOW | B18: 1.0 – 2.74 | C18: Green | D18: Standard cadence | E18: No | F18: All metrics within target. Continue monthly monitoring.
A19: MEDIUM | B19: 2.75 – 5.4 | C19: Amber | D19: Weekly PM check-in | E19: No | F19: One or more metrics underperforming. Initiate coaching.
A20: HIGH | B20: 3.25 – 10.0 | C20: Red | D20: 3x per week (PM) | E20: Yes | F20: Improvement plan within 5 working days. Review weekly.
A22: MAJOR EVENT OVERRIDE: Any team with a Major impact event this month is automatically scored HIGH regardless of composite score. This appears in col M of Monthly Matrix.
C23: HIGH threshold (>=) | D23: 2.75
A24: AMBER TARGET: Calculated per team as Operative Count × 2 per month. Zero amber reporting is treated as a risk signal, not a low-risk outcome. | C24: MEDIUM threshold (>=) | D24: 3.25
D25: 95
A26: AMBER FLOOR OVERRIDE: Teams submitting fewer than 20% of their amber target are automatically HIGH. This captures near-zero reporters, not just absolute zero. | C26: Amber floor threshold (score >= = AUTO HIGH) | D26: 2 | E26: Teams with amber score >= 8 (submitting < 20% of monthly target) are automatically rated HIGH regardless of composite score. Zero reporters score 10 and are always captured by this rule.

Sheet Monthly Matrix
A1: FIELD TEAM RISK MATRIX - MONTHLY SCORING
A2: Scores calculate automatically from Field Teams and Data tabs. Set date range in Dashboard: N1 = start date, O1 = end date. Regenerate Pole Results sheet after each quality data paste. RAG logic: Major event or amber score ≥8 forces HIGH regardless of composite. Inactive teams show blank scores and are excluded from all rankings.
A3: Team ID | B3: Team Name | C3: Contract | D3: NOD | E3: SOM | F3: CM | G3: PM | H3: Operative Count | I3: Amber Target | J3: Amber Count | K3: Red Alerts (Minor) | L3: Red Alerts (Mod/Maj) | M3: Major Event? | N3: Skillko (%) | O3: Skillko Score | P3: Non-Compliant Poles | Q3: Amber Score | R3: Red Alert Score | S3: Quality Score (rate) | T3: COMPOSITE SCORE (★1–5) | U3: ★ Amber | V3: ★ Red Alerts | W3: ★ Skillko | X3: ★ Quality | Y3: ★ SSV | Z3: ★ Composite | AA3: RAG | AB3: Rank (high) | AC3: Rank (low) | AD3: Rank Score (low-risk tie-break) | AE3: 4wk HIGH | AF3: Plan Required? | AG3: Date Start (helper) | AH3: Pole/Criteria Checks | AI3: Compliant Checks | AJ3: Date End (helper) | AK3: HIGH Rank (helper) | AL3: H+M Rank (helper) | AM3: Trend vs Prev Month | AN3: SSV Visit Count (helper) | AO3: SSV Score (1–5)
A4: ='Field Teams'!A5 | B4: ='Field Teams'!B5 | C4: ='Field Teams'!C5 | D4: ='Field Teams'!D5 | E4: ='Field Teams'!E5 | F4: ='Field Teams'!F5 | G4: ='Field Teams'!G5 | H4: ='Field Teams'!H5 | I4: =H4*2 | J4: =IFERROR(SUMPRODUCT((((ISNUMBER(SEARCH(B4,'Data - HSQE Events'!V$6:V$3000))+ISNUMBER(SEARCH(B4,'Data - HSQE Events'!H$6:H$3000)))>0))*('Data - HSQE Events'!F$6:F$3000>=$AG$3)*('Data - HSQE Events'!F$6:F$3000<=$AJ$3)*('Data - HSQE Events'!R$6:R$3000="Opportunity")),0) | K4: =IFERROR(SUMPRODUCT((((ISNUMBER(SEARCH(B4,'Data - HSQE Events'!V$6:V$3000))+ISNUMBER(SEARCH(B4,'Data - HSQE Events'!H$6:H$3000)))>0))*('Data - HSQE Events'!F$6:F$3000>=$AG$3)*('Data - HSQE Events'!F$6:F$3000<=$AJ$3)*('Data - HSQE Events'!R$6:R$3000="Minor")),0) | L4: =IFERROR(SUMPRODUCT((((ISNUMBER(SEARCH(B4,'Data - HSQE Events'!V$6:V$3000))+ISNUMBER(SEARCH(B4,'Data - HSQE Events'!H$6:H$3000)))>0))*('Data - HSQE Events'!F$6:F$3000>=$AG$3)*('Data - HSQE Events'!F$6:F$3000<=$AJ$3)*(('Data - HSQE Events'!R$6:R$3000="Moderate")+('Data - HSQE Events'!R$6:R$3000="Major"))),0) | M4: =IF(IFERROR(SUMPRODUCT((((ISNUMBER(SEARCH(B4,'Data - HSQE Events'!V$6:V$3000))+ISNUMBER(SEARCH(B4,'Data - HSQE Events'!H$6:H$3000)))>0))*('Data - HSQE Events'!F$6:F$3000>=$AG$3)*('Data - HSQE Events'!F$6:F$3000<=$AJ$3)*('Data - HSQE Events'!R$6:R$3000="Major")),0)>0,"YES","NO") | N4: =IFERROR(SUMPRODUCT(('Data - Skillko'!B$6:B$3000=B4)*('Data - Skillko'!C$6:C$3000="Total")*('Data - Skillko'!E$6:E$3000))*100,0) | O4: =ROUND(MAX(1,MIN(5,1+N4/100*4)),1) | P4: =IFERROR(SUMPRODUCT(ISNUMBER(SEARCH(B4,'Pole Results'!$A$13:$A$2000))*('Pole Results'!$B$13:$B$2000>=$AG$3)*('Pole Results'!$B$13:$B$2000<=$AE$3)*('Pole Results'!$E$13:$E$2000="Non-Compliant")),0) | Q4: =IF(I4=0,1,IFERROR(ROUND(MAX(1,MIN(5,1+J4/I4*4)),1),3)) | R4: =ROUND(6-MAX(MIN(5,K4*0.8+1),MIN(5,L4*2+1)),1) | S4: =IFERROR(ROUND(MAX(1,MIN(5,5-(P4/MAX(1,AI4))*4)),1),5) | T4: =IF('Field Teams'!$I$5="Inactive","",ROUND((Q4*Settings!$D$6+R4*Settings!$D$7+O4*Settings!$D$10+S4*Settings!$D$12+AO4*Settings!$D$13)/Settings!$D$14,1)) | U4: =IF('Field Teams'!$I$5="Inactive","",IF(Q4="","",IF(Q4>=4.5,"★★★★★",IF(Q4>=3.5,"★★★★☆",IF(Q4>=2.5,"★★★☆☆",IF(Q4>=1.5,"★★☆☆☆","★☆☆☆☆")))))) | V4: =IF('Field Teams'!$I$5="Inactive","",IF(R4="","",IF(R4>=4.5,"★★★★★",IF(R4>=3.5,"★★★★☆",IF(R4>=2.5,"★★★☆☆",IF(R4>=1.5,"★★☆☆☆","★☆☆☆☆")))))) | W4: =IF('Field Teams'!$I$5="Inactive","",IF(O4="","",IF(O4>=4.5,"★★★★★",IF(O4>=3.5,"★★★★☆",IF(O4>=2.5,"★★★☆☆",IF(O4>=1.5,"★★☆☆☆","★☆☆☆☆")))))) | X4: =IF('Field Teams'!$I$5="Inactive","",IF(S4="","",IF(S4>=4.5,"★★★★★",IF(S4>=3.5,"★★★★☆",IF(S4>=2.5,"★★★☆☆",IF(S4>=1.5,"★★☆☆☆","★☆☆☆☆")))))) | Y4: =IF('Field Teams'!$I$5="Inactive","",IF(AO4="","",IF(AO4>=4.5,"★★★★★",IF(AO4>=3.5,"★★★★☆",IF(AO4>=2.5,"★★★☆☆",IF(AO4>=1.5,"★★☆☆☆","★☆☆☆☆")))))) | Z4: =IF('Field Teams'!$I$5="Inactive","",IF(T4="","",IF(T4>=4.5,"★★★★★",IF(T4>=3.5,"★★★★☆",IF(T4>=2.5,"★★★☆☆",IF(T4>=1.5,"★★☆☆☆","★☆☆☆☆")))))) | AA4: =IF('Field Teams'!$I$5="Inactive","",IF(M4="YES","HIGH",IF(Q4<=Settings!$D$26,"HIGH",IF(T4<=Settings!$D$23,"HIGH",IF(T4<=Settings!$D$24,"MEDIUM","LOW"))))) | AB4: =IF('Field Teams'!$I$5="Inactive",-1,IFERROR((6-T4)+(77-ROW())*0.0001,0)) | AC4: =IF('Field Teams'!$I$5="Inactive",999,IFERROR((6-T4)+(ROW()-3)*0.0001,99)) | AD4: =IF('Field Teams'!$I$5="Inactive",999,IFERROR(AB4+(ROW()-3)*0.0001,99)) | AE4: 0 | AF4: =IF('Field Teams'!$I$5="Inactive","",IF(AA4="HIGH","YES - within 5 working days","")) | AH4: =IFERROR(SUMPRODUCT(ISNUMBER(SEARCH(B4,'Pole Results'!$A$13:$A$2000))*('Pole Results'!$B$13:$B$2000>=$AG$3)*('Pole Results'!$B$13:$B$2000<=$AE$3)),0) | AI4: =IFERROR(SUMPRODUCT(ISNUMBER(SEARCH(B4,'Pole Results'!$A$13:$A$2000))*('Pole Results'!$B$13:$B$2000>=$AG$3)*('Pole Results'!$B$13:$B$2000<=$AE$3)*('Pole Results'!$E$13:$E$2000="Compliant")),0) | AK4: =IF('Field Teams'!$I$5="Inactive",-1,IF(AA4="HIGH",AB4,-1)) | AL4: =IF('Field Teams'!$I$5="Inactive",-1,IF(OR(AA4="HIGH",AA4="MEDIUM"),AB4,-1)) | AM4: =IF('Field Teams'!$I$5="Inactive","",IF(IFERROR(LOOKUP(2,1/('Historical Scores'!C5:N5<>""),'Historical Scores'!C5:N5),"")="","New",IF(T4=""," ",IF(T4>IFERROR(LOOKUP(2,1/('Historical Scores'!C5:N5<>""),'Historical Scores'!C5:N5),""),"▲ Worsening",IF(T4<IFERROR(LOOKUP(2,1/('Historical Scores'!C5:N5<>""),'Historical Scores'!C5:N5),""),"▼ Improving","► Stable"))))) | AN4: =IFERROR(SUMPRODUCT((ISNUMBER(SEARCH(B4,'Data - SSV'!AE$6:AE$3000)))*('Data - SSV'!AF$6:AF$3000>=(AJ$3-90))*('Data - SSV'!AF$6:AF$3000<=AJ$3)*('Data - SSV'!AH$6:AH$3000<>"")),0) | AO4: =IF('Field Teams'!$I$5="Inactive","",IF(AN4=0,3,IF(AN4=1,IF(IFERROR(SUMPRODUCT((ISNUMBER(SEARCH(B4,'Data - SSV'!AE$6:AE$3000)))*('Data - SSV'!AF$6:AF$3000>=(AJ$3-90))*('Data - SSV'!AF$6:AF$3000<=AJ$3)*('Data - SSV'!AH$6:AH$3000<>"")*IF('Data - SSV'!AH$6:AH$3000="",0,'Data - SSV'!AH$6:AH$3000))/AN4,3)=4,4,IF(IFERROR(SUMPRODUCT((ISNUMBER(SEARCH(B4,'Data - SSV'!AE$6:AE$3000)))*('Data - SSV'!AF$6:AF$3000>=(AJ$3-90))*('Data - SSV'!AF$6:AF$3000<=AJ$3)*('Data - SSV'!AH$6:AH$3000<>"")*IF('Data - SSV'!AH$6:AH$3000="",0,'Data - SSV'!AH$6:AH$3000))/AN4,3)>=3,3,IF(IFERROR(SUMPRODUCT((ISNUMBER(SEARCH(B4,'Data - SSV'!AE$6:AE$3000)))*('Data - SSV'!AF$6:AF$3000>=(AJ$3-90))*('Data - SSV'!AF$6:AF$3000<=AJ$3)*('Data - SSV'!AH$6:AH$3000<>"")*IF('Data - SSV'!AH$6:AH$3000="",0,'Data - SSV'!AH$6:AH$3000))/AN4,3)>=2,2,1))),IF(IFERROR(SUMPRODUCT((ISNUMBER(SEARCH(B4,'Data - SSV'!AE$6:AE$3000)))*('Data - SSV'!AF$6:AF$3000>=(AJ$3-90))*('Data - SSV'!AF$6:AF$3000<=AJ$3)*('Data - SSV'!AH$6:AH$3000<>"")*IF('Data - SSV'!AH$6:AH$3000="",0,'Data - SSV'!AH$6:AH$3000))/AN4,3)=4,5,IF(IFERROR(SUMPRODUCT((ISNUMBER(SEARCH(B4,'Data - SSV'!AE$6:AE$3000)))*('Data - SSV'!AF$6:AF$3000>=(AJ$3-90))*('Data - SSV'!AF$6:AF$3000<=AJ$3)*('Data - SSV'!AH$6:AH$3000<>"")*IF('Data - SSV'!AH$6:AH$3000="",0,'Data - SSV'!AH$6:AH$3000))/AN4,3)>=3.5,4,IF(IFERROR(SUMPRODUCT((ISNUMBER(SEARCH(B4,'Data - SSV'!AE$6:AE$3000)))*('Data - SSV'!AF$6:AF$3000>=(AJ$3-90))*('Data - SSV'!AF$6:AF$3000<=AJ$3)*('Data - SSV'!AH$6:AH$3000<>"")*IF('Data - SSV'!AH$6:AH$3000="",0,'Data - SSV'!AH$6:AH$3000))/AN4,3)>=3,3,IF(IFERROR(SUMPRODUCT((ISNUMBER(SEARCH(B4,'Data - SSV'!AE$6:AE$3000)))*('Data - SSV'!AF$6:AF$3000>=(AJ$3-90))*('Data - SSV'!AF$6:AF$3000<=AJ$3)*('Data - SSV'!AH$6:AH$3000<>"")*IF('Data - SSV'!AH$6:AH$3000="",0,'Data - SSV'!AH$6:AH$3000))/AN4,3)>=2,2,1)))))))
A5: ='Field Teams'!A6 | B5: ='Field Teams'!B6 | C5: ='Field Teams'!C6 | D5: ='Field Teams'!D6 | E5: ='Field Teams'!E6 | F5: ='Field Teams'!F6 | G5: ='Field Teams'!G6 | H5: ='Field Teams'!H6 | I5: =H5*2 | J5: =IFERROR(SUMPRODUCT((((ISNUMBER(SEARCH(B5,'Data - HSQE Events'!V$6:V$3000))+ISNUMBER(SEARCH(B5,'Data - HSQE Events'!H$6:H$3000)))>0))*('Data - HSQE Events'!F$6:F$3000>=$AG$3)*('Data - HSQE Events'!F$6:F$3000<=$AJ$3)*('Data - HSQE Events'!R$6:R$3000="Opportunity")),0) | K5: =IFERROR(SUMPRODUCT((((ISNUMBER(SEARCH(B5,'Data - HSQE Events'!V$6:V$3000))+ISNUMBER(SEARCH(B5,'Data - HSQE Events'!H$6:H$3000)))>0))*('Data - HSQE Events'!F$6:F$3000>=$AG$3)*('Data - HSQE Events'!F$6:F$3000<=$AJ$3)*('Data - HSQE Events'!R$6:R$3000="Minor")),0) | L5: =IFERROR(SUMPRODUCT((((ISNUMBER(SEARCH(B5,'Data - HSQE Events'!V$6:V$3000))+ISNUMBER(SEARCH(B5,'Data - HSQE Events'!H$6:H$3000)))>0))*('Data - HSQE Events'!F$6:F$3000>=$AG$3)*('Data - HSQE Events'!F$6:F$3000<=$AJ$3)*(('Data - HSQE Events'!R$6:R$3000="Moderate")+('Data - HSQE Events'!R$6:R$3000="Major"))),0) | M5: =IF(IFERROR(SUMPRODUCT((((ISNUMBER(SEARCH(B5,'Data - HSQE Events'!V$6:V$3000))+ISNUMBER(SEARCH(B5,'Data - HSQE Events'!H$6:H$3000)))>0))*('Data - HSQE Events'!F$6:F$3000>=$AG$3)*('Data - HSQE Events'!F$6:F$3000<=$AJ$3)*('Data - HSQE Events'!R$6:R$3000="Major")),0)>0,"YES","NO") | N5: =IFERROR(SUMPRODUCT(('Data - Skillko'!B$6:B$3000=B5)*('Data - Skillko'!C$6:C$3000="Total")*('Data - Skillko'!E$6:E$3000))*100,0) | O5: =ROUND(MAX(1,MIN(5,1+N5/100*4)),1) | P5: =IFERROR(SUMPRODUCT(ISNUMBER(SEARCH(B5,'Pole Results'!$A$13:$A$2000))*('Pole Results'!$B$13:$B$2000>=$AG$3)*('Pole Results'!$B$13:$B$2000<=$AE$3)*('Pole Results'!$E$13:$E$2000="Non-Compliant")),0) | Q5: =IF(I5=0,1,IFERROR(ROUND(MAX(1,MIN(5,1+J5/I5*4)),1),3)) | R5: =ROUND(6-MAX(MIN(5,K5*0.8+1),MIN(5,L5*2+1)),1) | S5: =IFERROR(ROUND(MAX(1,MIN(5,5-(P5/MAX(1,AI5))*4)),1),5) | T5: =IF('Field Teams'!$I$6="Inactive","",ROUND((Q5*Settings!$D$6+R5*Settings!$D$7+O5*Settings!$D$10+S5*Settings!$D$12+AO5*Settings!$D$13)/Settings!$D$14,1)) | U5: =IF('Field Teams'!$I$6="Inactive","",IF(Q5="","",IF(Q5>=4.5,"★★★★★",IF(Q5>=3.5,"★★★★☆",IF(Q5>=2.5,"★★★☆☆",IF(Q5>=1.5,"★★☆☆☆","★☆☆☆☆")))))) | V5: =IF('Field Teams'!$I$6="Inactive","",IF(R5="","",IF(R5>=4.5,"★★★★★",IF(R5>=3.5,"★★★★☆",IF(R5>=2.5,"★★★☆☆",IF(R5>=1.5,"★★☆☆☆","★☆☆☆☆")))))) | W5: =IF('Field Teams'!$I$6="Inactive","",IF(O5="","",IF(O5>=4.5,"★★★★★",IF(O5>=3.5,"★★★★☆",IF(O5>=2.5,"★★★☆☆",IF(O5>=1.5,"★★☆☆☆","★☆☆☆☆")))))) | X5: =IF('Field Teams'!$I$6="Inactive","",IF(S5="","",IF(S5>=4.5,"★★★★★",IF(S5>=3.5,"★★★★☆",IF(S5>=2.5,"★★★☆☆",IF(S5>=1.5,"★★☆☆☆","★☆☆☆☆")))))) | Y5: =IF('Field Teams'!$I$6="Inactive","",IF(AO5="","",IF(AO5>=4.5,"★★★★★",IF(AO5>=3.5,"★★★★☆",IF(AO5>=2.5,"★★★☆☆",IF(AO5>=1.5,"★★☆☆☆","★☆☆☆☆")))))) | Z5: =IF('Field Teams'!$I$5="Inactive","",IF(T5="","",IF(T5>=4.5,"★★★★★",IF(T5>=3.5,"★★★★☆",IF(T5>=2.5,"★★★☆☆",IF(T5>=1.5,"★★☆☆☆","★☆☆☆☆")))))) | AA5: =IF('Field Teams'!$I$6="Inactive","",IF(M5="YES","HIGH",IF(Q5<=Settings!$D$26,"HIGH",IF(T5<=Settings!$D$23,"HIGH",IF(T5<=Settings!$D$24,"MEDIUM","LOW"))))) | AB5: =IF('Field Teams'!$I$5="Inactive",-1,IFERROR((6-T5)+(77-ROW())*0.0001,0)) | AC5: =IF('Field Teams'!$I$5="Inactive",999,IFERROR((6-T5)+(ROW()-3)*0.0001,99)) | AD5: =IF('Field Teams'!$I$6="Inactive",999,IFERROR(AB5+(ROW()-3)*0.0001,99)) | AE5: 0 | AF5: =IF('Field Teams'!$I$6="Inactive","",IF(AA5="HIGH","YES - within 5 working days","")) | AH5: =IFERROR(SUMPRODUCT(ISNUMBER(SEARCH(B5,'Pole Results'!$A$13:$A$2000))*('Pole Results'!$B$13:$B$2000>=$AG$3)*('Pole Results'!$B$13:$B$2000<=$AE$3)),0) | AI5: =IFERROR(SUMPRODUCT(ISNUMBER(SEARCH(B5,'Pole Results'!$A$13:$A$2000))*('Pole Results'!$B$13:$B$2000>=$AG$3)*('Pole Results'!$B$13:$B$2000<=$AE$3)*('Pole Results'!$E$13:$E$2000="Compliant")),0) | AK5: =IF('Field Teams'!$I$6="Inactive",-1,IF(AA5="HIGH",AB5,-1)) | AL5: =IF('Field Teams'!$I$6="Inactive",-1,IF(OR(AA5="HIGH",AA5="MEDIUM"),AB5,-1)) | AM5: =IF('Field Teams'!$I$6="Inactive","",IF(IFERROR(LOOKUP(2,1/('Historical Scores'!C6:N6<>""),'Historical Scores'!C6:N6),"")="","New",IF(T5=""," ",IF(T5>IFERROR(LOOKUP(2,1/('Historical Scores'!C6:N6<>""),'Historical Scores'!C6:N6),""),"▲ Worsening",IF(T5<IFERROR(LOOKUP(2,1/('Historical Scores'!C6:N6<>""),'Historical Scores'!C6:N6),""),"▼ Improving","► Stable"))))) | AN5: =IFERROR(SUMPRODUCT((ISNUMBER(SEARCH(B5,'Data - SSV'!AE$6:AE$3000)))*('Data - SSV'!AF$6:AF$3000>=(AJ$3-90))*('Data - SSV'!AF$6:AF$3000<=AJ$3)*('Data - SSV'!AH$6:AH$3000<>"")),0) | AO5: =IF('Field Teams'!$I$6="Inactive","",IF(AN5=0,3,IF(AN5=1,IF(IFERROR(SUMPRODUCT((ISNUMBER(SEARCH(B5,'Data - SSV'!AE$6:AE$3000)))*('Data - SSV'!AF$6:AF$3000>=(AJ$3-90))*('Data - SSV'!AF$6:AF$3000<=AJ$3)*('Data - SSV'!AH$6:AH$3000<>"")*IF('Data - SSV'!AH$6:AH$3000="",0,'Data - SSV'!AH$6:AH$3000))/AN5,3)=4,4,IF(IFERROR(SUMPRODUCT((ISNUMBER(SEARCH(B5,'Data - SSV'!AE$6:AE$3000)))*('Data - SSV'!AF$6:AF$3000>=(AJ$3-90))*('Data - SSV'!AF$6:AF$3000<=AJ$3)*('Data - SSV'!AH$6:AH$3000<>"")*IF('Data - SSV'!AH$6:AH$3000="",0,'Data - SSV'!AH$6:AH$3000))/AN5,3)>=3,3,IF(IFERROR(SUMPRODUCT((ISNUMBER(SEARCH(B5,'Data - SSV'!AE$6:AE$3000)))*('Data - SSV'!AF$6:AF$3000>=(AJ$3-90))*('Data - SSV'!AF$6:AF$3000<=AJ$3)*('Data - SSV'!AH$6:AH$3000<>"")*IF('Data - SSV'!AH$6:AH$3000="",0,'Data - SSV'!AH$6:AH$3000))/AN5,3)>=2,2,1))),IF(IFERROR(SUMPRODUCT((ISNUMBER(SEARCH(B5,'Data - SSV'!AE$6:AE$3000)))*('Data - SSV'!AF$6:AF$3000>=(AJ$3-90))*('Data - SSV'!AF$6:AF$3000<=AJ$3)*('Data - SSV'!AH$6:AH$3000<>"")*IF('Data - SSV'!AH$6:AH$3000="",0,'Data - SSV'!AH$6:AH$3000))/AN5,3)=4,5,IF(IFERROR(SUMPRODUCT((ISNUMBER(SEARCH(B5,'Data - SSV'!AE$6:AE$3000)))*('Data - SSV'!AF$6:AF$3000>=(AJ$3-90))*('Data - SSV'!AF$6:AF$3000<=AJ$3)*('Data - SSV'!AH$6:AH$3000<>"")*IF('Data - SSV'!AH$6:AH$3000="",0,'Data - SSV'!AH$6:AH$3000))/AN5,3)>=3.5,4,IF(IFERROR(SUMPRODUCT((ISNUMBER(SEARCH(B5,'Data - SSV'!AE$6:AE$3000)))*('Data - SSV'!AF$6:AF$3000>=(AJ$3-90))*('Data - SSV'!AF$6:AF$3000<=AJ$3)*('Data - SSV'!AH$6:AH$3000<>"")*IF('Data - SSV'!AH$6:AH$3000="",0,'Data - SSV'!AH$6:AH$3000))/AN5,3)>=3,3,IF(IFERROR(SUMPRODUCT((ISNUMBER(SEARCH(B5,'Data - SSV'!AE$6:AE$3000)))*('Data - SSV'!AF$6:AF$3000>=(AJ$3-90))*('Data - SSV'!AF$6:AF$3000<=AJ$3)*('Data - SSV'!AH$6:AH$3000<>"")*IF('Data - SSV'!AH$6:AH$3000="",0,'Data - SSV'!AH$6:AH$3000))/AN5,3)>=2,2,1)))))))
